<?xml version="1.0" ?>
<robot name="ros_robot" xmlns:xacro="http://www.ros.org/wiki/xacro">

<xacro:include filename="$(find ros_robot_description)/urdf/materials.xacro" />
<xacro:include filename="$(find ros_robot_description)/urdf/ros_robot.trans" />
<xacro:include filename="$(find ros_robot_description)/urdf/ros_robot.gazebo" />
<link name="base_link">
  <inertial>
    <origin rpy="0 0 0" xyz="0.1158388397613685 0.10109007722221264 0.05032988922468174"/>
    <mass value="1.2049572619011009"/>
    <inertia ixx="0.002389" ixy="5.9e-05" ixz="-2e-06" iyy="0.005092" iyz="2e-06" izz="0.006572"/>
  </inertial>
  <visual>
    <origin rpy="0 0 0" xyz="0 0 0"/>
    <geometry>
      <mesh filename="package://ros_robot_description/meshes/base_link.stl" scale="0.001 0.001 0.001"/>
    </geometry>
    <material name="silver"/>
  </visual>
  <collision>
    <origin rpy="0 0 0" xyz="0 0 0"/>
    <geometry>
      <mesh filename="package://ros_robot_description/meshes/base_link.stl" scale="0.001 0.001 0.001"/>
    </geometry>
  </collision>
</link>

<link name="top_plate_1">
  <inertial>
    <origin rpy="0 0 0" xyz="0.11575137352044365 0.048604813248326516 0.09148906722549498"/>
    <mass value="0.4447990619720318"/>
    <inertia ixx="0.000409" ixy="-0.0" ixz="0.0" iyy="0.0012" iyz="0.0" izz="0.001609"/>
  </inertial>
  <visual>
    <origin rpy="0 0 0" xyz="-0.0 -0.0525 -0.0"/>
    <geometry>
      <mesh filename="package://ros_robot_description/meshes/top_plate_1.stl" scale="0.001 0.001 0.001"/>
    </geometry>
    <material name="silver"/>
  </visual>
  <collision>
    <origin rpy="0 0 0" xyz="-0.0 -0.0525 -0.0"/>
    <geometry>
      <mesh filename="package://ros_robot_description/meshes/top_plate_1.stl" scale="0.001 0.001 0.001"/>
    </geometry>
  </collision>
</link>

<link name="wheel_rear_left_1">
  <inertial>
    <origin rpy="0 0 0" xyz="0.1858039345670089 -0.019395186751674044 0.05498906722549458"/>
    <mass value="2.4569736880507413"/>
    <inertia ixx="0.001869" ixy="-0.0" ixz="0.0" iyy="0.003083" iyz="-0.0" izz="0.001869"/>
  </inertial>
  <visual>
    <origin rpy="0 0 0" xyz="-0.0 -0.04 -0.0"/>
    <geometry>
      <mesh filename="package://ros_robot_description/meshes/wheel_rear_left_1.stl" scale="0.001 0.001 0.001"/>
    </geometry>
    <material name="silver"/>
  </visual>
  <collision>
    <origin rpy="0 0 0" xyz="-0.0 -0.04 -0.0"/>
    <geometry>
      <mesh filename="package://ros_robot_description/meshes/wheel_rear_left_1.stl" scale="0.001 0.001 0.001"/>
    </geometry>
  </collision>
</link>

<link name="kinect_1">
  <inertial>
    <origin rpy="0 0 0" xyz="0.03605493456701083 0.06835581324832721 0.10360039458001304"/>
    <mass value="0.9942712642270771"/>
    <inertia ixx="0.000665" ixy="-0.0" ixz="0.0" iyy="0.000479" iyz="-0.0" izz="0.001077"/>
  </inertial>
  <visual>
    <origin rpy="0 0 0" xyz="-0.039749 -0.032749 0.0"/>
    <geometry>
      <mesh filename="package://ros_robot_description/meshes/kinect_1.stl" scale="0.001 0.001 0.001"/>
    </geometry>
    <material name="silver"/>
  </visual>
  <collision>
    <origin rpy="0 0 0" xyz="-0.039749 -0.032749 0.0"/>
    <geometry>
      <mesh filename="package://ros_robot_description/meshes/kinect_1.stl" scale="0.001 0.001 0.001"/>
    </geometry>
  </collision>
</link>

<link name="motor_right_1">
  <inertial>
    <origin rpy="0 0 0" xyz="0.18580393456701955 0.16772635147626097 0.04984029245709425"/>
    <mass value="0.5120118768661088"/>
    <inertia ixx="0.000373" ixy="-0.0" ixz="0.0" iyy="6.5e-05" iyz="4e-06" izz="0.000372"/>
  </inertial>
  <visual>
    <origin rpy="0 0 0" xyz="-0.0 0.0603 -0.006"/>
    <geometry>
      <mesh filename="package://ros_robot_description/meshes/motor_right_1.stl" scale="0.001 0.001 0.001"/>
    </geometry>
    <material name="silver"/>
  </visual>
  <collision>
    <origin rpy="0 0 0" xyz="-0.0 0.0603 -0.006"/>
    <geometry>
      <mesh filename="package://ros_robot_description/meshes/motor_right_1.stl" scale="0.001 0.001 0.001"/>
    </geometry>
  </collision>
</link>

<link name="motor_left_1">
  <inertial>
    <origin rpy="0 0 0" xyz="0.05665515979861051 0.15508327502039337 0.04398906722550343"/>
    <mass value="0.512011876866109"/>
    <inertia ixx="0.000372" ixy="-4e-06" ixz="0.0" iyy="6.5e-05" iyz="0.0" izz="0.000373"/>
  </inertial>
  <visual>
    <origin rpy="0 0 0" xyz="-0.0 0.0603 -0.006"/>
    <geometry>
      <mesh filename="package://ros_robot_description/meshes/motor_left_1.stl" scale="0.001 0.001 0.001"/>
    </geometry>
    <material name="silver"/>
  </visual>
  <collision>
    <origin rpy="0 0 0" xyz="-0.0 0.0603 -0.006"/>
    <geometry>
      <mesh filename="package://ros_robot_description/meshes/motor_left_1.stl" scale="0.001 0.001 0.001"/>
    </geometry>
  </collision>
</link>

<link name="wheel_front_left_1">
  <inertial>
    <origin rpy="0 0 0" xyz="0.05580393456700972 -0.018395186751673665 0.04998906722549404"/>
    <mass value="2.4569736880507413"/>
    <inertia ixx="0.001869" ixy="-0.0" ixz="0.0" iyy="0.003083" iyz="-0.0" izz="0.001869"/>
  </inertial>
  <visual>
    <origin rpy="0 0 0" xyz="-0.0 -0.04 -0.0"/>
    <geometry>
      <mesh filename="package://ros_robot_description/meshes/wheel_front_left_1.stl" scale="0.001 0.001 0.001"/>
    </geometry>
    <material name="silver"/>
  </visual>
  <collision>
    <origin rpy="0 0 0" xyz="-0.0 -0.04 -0.0"/>
    <geometry>
      <mesh filename="package://ros_robot_description/meshes/wheel_front_left_1.stl" scale="0.001 0.001 0.001"/>
    </geometry>
  </collision>
</link>

<link name="wheel_rear_right_1">
  <inertial>
    <origin rpy="0 0 0" xyz="0.18580393456700908 0.18060481324832814 0.04998906722549435"/>
    <mass value="2.4569736880507413"/>
    <inertia ixx="0.001869" ixy="0.0" ixz="0.0" iyy="0.003083" iyz="0.0" izz="0.001869"/>
  </inertial>
  <visual>
    <origin rpy="0 0 0" xyz="-0.0 -0.0 -0.0"/>
    <geometry>
      <mesh filename="package://ros_robot_description/meshes/wheel_rear_right_1.stl" scale="0.001 0.001 0.001"/>
    </geometry>
    <material name="silver"/>
  </visual>
  <collision>
    <origin rpy="0 0 0" xyz="-0.0 -0.0 -0.0"/>
    <geometry>
      <mesh filename="package://ros_robot_description/meshes/wheel_rear_right_1.stl" scale="0.001 0.001 0.001"/>
    </geometry>
  </collision>
</link>

<link name="wheel_front_right_1">
  <inertial>
    <origin rpy="0 0 0" xyz="0.0508039345670098 0.1806048132483284 0.04998906722549405"/>
    <mass value="2.4569736880507413"/>
    <inertia ixx="0.001869" ixy="-0.0" ixz="0.0" iyy="0.003083" iyz="0.0" izz="0.001869"/>
  </inertial>
  <visual>
    <origin rpy="0 0 0" xyz="-0.0 -0.0 0.0"/>
    <geometry>
      <mesh filename="package://ros_robot_description/meshes/wheel_front_right_1.stl" scale="0.001 0.001 0.001"/>
    </geometry>
    <material name="silver"/>
  </visual>
  <collision>
    <origin rpy="0 0 0" xyz="-0.0 -0.0 0.0"/>
    <geometry>
      <mesh filename="package://ros_robot_description/meshes/wheel_front_right_1.stl" scale="0.001 0.001 0.001"/>
    </geometry>
  </collision>
</link>

<joint name="Rigid3" type="fixed">
  <origin rpy="0 0 0" xyz="0.0 0.0525 0.0"/>
  <parent link="base_link"/>
  <child link="top_plate_1"/>
</joint>

<joint name="Rev5" type="continuous">
  <origin rpy="0 0 0" xyz="0.0 0.04 0.0"/>
  <parent link="base_link"/>
  <child link="wheel_rear_left_1"/>
  <axis xyz="0.0 -1.0 0.0"/>
</joint>

<joint name="Rigid8" type="fixed">
  <origin rpy="0 0 0" xyz="0.039749 -0.019751 -0.0"/>
  <parent link="top_plate_1"/>
  <child link="kinect_1"/>
</joint>

<joint name="Rigid9" type="fixed">
  <origin rpy="0 0 0" xyz="0.0 -0.0603 0.006"/>
  <parent link="base_link"/>
  <child link="motor_right_1"/>
</joint>

<joint name="Rigid10" type="fixed">
  <origin rpy="0 0 0" xyz="0.0 -0.0603 0.006"/>
  <parent link="base_link"/>
  <child link="motor_left_1"/>
</joint>

<joint name="Rev11" type="continuous">
  <origin rpy="0 0 0" xyz="0.0 0.1003 -0.006"/>
  <parent link="motor_left_1"/>
  <child link="wheel_front_left_1"/>
  <axis xyz="0.0 -1.0 0.0"/>
</joint>

<joint name="Rev12" type="continuous">
  <origin rpy="0 0 0" xyz="0.0 0.0603 -0.006"/>
  <parent link="motor_right_1"/>
  <child link="wheel_rear_right_1"/>
  <axis xyz="-0.0 1.0 -0.0"/>
</joint>

<joint name="Rigid14" type="fixed">
  <origin rpy="0 0 0" xyz="0.0 0.0 0.0"/>
  <parent link="base_link"/>
  <child link="wheel_front_right_1"/>
</joint>

</robot>
